<?xml version="1.0" encoding="UTF-8"?>
<testng-results skipped="0" failed="1" ignored="0" total="1" passed="0">
  <reporter-output>
  </reporter-output>
  <suite name="Default suite" duration-ms="38725" started-at="2021-02-19T17:44:54 BDT" finished-at="2021-02-19T17:45:33 BDT">
    <groups>
    </groups>
    <test name="Default test" duration-ms="38725" started-at="2021-02-19T17:44:54 BDT" finished-at="2021-02-19T17:45:33 BDT">
      <class name="Run_Class.Test_Case_Run_Class">
        <test-method status="PASS" signature="Base_Class_Run()[pri:0, instance:Run_Class.Test_Case_Run_Class@711f39f9]" name="Base_Class_Run" is-config="true" duration-ms="19988" started-at="2021-02-19T17:44:54 BDT" finished-at="2021-02-19T17:45:14 BDT">
          <reporter-output>
          </reporter-output>
        </test-method> <!-- Base_Class_Run -->
        <test-method status="FAIL" signature="Test_Case_05_Run()[pri:0, instance:Run_Class.Test_Case_Run_Class@711f39f9]" name="Test_Case_05_Run" duration-ms="18598" started-at="2021-02-19T17:45:14 BDT" finished-at="2021-02-19T17:45:33 BDT">
          <exception class="java.lang.AssertionError">
            <message>
              <![CDATA[did not expect to find [280.97] but found [281.97]]]>
            </message>
            <full-stacktrace>
              <![CDATA[java.lang.AssertionError: did not expect to find [280.97] but found [281.97]
at org.testng.Assert.fail(Assert.java:97)
at org.testng.Assert.failNotEquals(Assert.java:969)
at org.testng.Assert.assertEquals(Assert.java:640)
at org.testng.Assert.assertEquals(Assert.java:651)
at Test_Case_05.Test_Case_05.Test_Case_05_Functionality(Test_Case_05.java:85)
at Test_Case_05.Test_Case_05.Test_Case_05_Functionality_Exception(Test_Case_05.java:101)
at Run_Class.Test_Case_Run_Class.Test_Case_05_Run(Test_Case_Run_Class.java:31)
at sun.reflect.NativeMethodAccessorImpl.invoke0(Native Method)
at sun.reflect.NativeMethodAccessorImpl.invoke(Unknown Source)
at sun.reflect.DelegatingMethodAccessorImpl.invoke(Unknown Source)
at java.lang.reflect.Method.invoke(Unknown Source)
at org.testng.internal.MethodInvocationHelper.invokeMethod(MethodInvocationHelper.java:133)
at org.testng.internal.TestInvoker.invokeMethod(TestInvoker.java:584)
at org.testng.internal.TestInvoker.invokeTestMethod(TestInvoker.java:172)
at org.testng.internal.MethodRunner.runInSequence(MethodRunner.java:46)
at org.testng.internal.TestInvoker$MethodInvocationAgent.invoke(TestInvoker.java:804)
at org.testng.internal.TestInvoker.invokeTestMethods(TestInvoker.java:145)
at org.testng.internal.TestMethodWorker.invokeTestMethods(TestMethodWorker.java:146)
at org.testng.internal.TestMethodWorker.run(TestMethodWorker.java:128)
at java.util.ArrayList.forEach(Unknown Source)
at org.testng.TestRunner.privateRun(TestRunner.java:770)
at org.testng.TestRunner.run(TestRunner.java:591)
at org.testng.SuiteRunner.runTest(SuiteRunner.java:402)
at org.testng.SuiteRunner.runSequentially(SuiteRunner.java:396)
at org.testng.SuiteRunner.privateRun(SuiteRunner.java:355)
at org.testng.SuiteRunner.run(SuiteRunner.java:304)
at org.testng.SuiteRunnerWorker.runSuite(SuiteRunnerWorker.java:53)
at org.testng.SuiteRunnerWorker.run(SuiteRunnerWorker.java:96)
at org.testng.TestNG.runSuitesSequentially(TestNG.java:1180)
at org.testng.TestNG.runSuitesLocally(TestNG.java:1102)
at org.testng.TestNG.runSuites(TestNG.java:1032)
at org.testng.TestNG.run(TestNG.java:1000)
at org.testng.remote.AbstractRemoteTestNG.run(AbstractRemoteTestNG.java:115)
at org.testng.remote.RemoteTestNG.initAndRun(RemoteTestNG.java:251)
at org.testng.remote.RemoteTestNG.main(RemoteTestNG.java:77)
]]>
            </full-stacktrace>
          </exception> <!-- java.lang.AssertionError -->
          <reporter-output>
          </reporter-output>
        </test-method> <!-- Test_Case_05_Run -->
      </class> <!-- Run_Class.Test_Case_Run_Class -->
    </test> <!-- Default test -->
  </suite> <!-- Default suite -->
</testng-results>
